<robot name="onshape">
<link name="servo">
<visual>
<origin xyz="0.032718666788579785221 -0.026375442291109735954 0.0073018751187259589575" rpy="0 -0 0" />
<geometry>
<mesh filename="package:///servo.stl"/>
</geometry>
<material name="servo_material">
<color rgba="0.61568627450980395466 0.81176470588235294379 0.92941176470588238168 1.0"/>
</material>
</visual>
<collision>
<origin xyz="0.032718666788579785221 -0.026375442291109735954 0.0073018751187259589575" rpy="0 -0 0" />
<geometry>
<mesh filename="package:///servo.stl"/>
</geometry>
</collision>
<inertial>
<origin xyz="0.032652007527250198615 -0.026375441741982637994 0.023301874940578035794" rpy="0 0 0"/>
<mass value="0.093399232466800610752" />
<inertia ixx="1.3101911709957606207e-05" ixy="-1.9163164104932232372e-13"  ixz="1.9890621813240049023e-13" iyy="2.4292764890865188316e-05" iyz="4.936677392002600175e-13" izz="2.1087845681977408194e-05" />
</inertial>
</link>

<link name="servo_2">
<visual>
<origin xyz="0 0.016000000000000000333 -0.022610000000000005094" rpy="1.570796326794896558 1.570796326794896558 0" />
<geometry>
<mesh filename="package:///servo.stl"/>
</geometry>
<material name="servo_material">
<color rgba="0.61568627450980395466 0.81176470588235294379 0.92941176470588238168 1.0"/>
</material>
</visual>
<collision>
<origin xyz="0 0.016000000000000000333 -0.022610000000000005094" rpy="1.570796326794896558 1.570796326794896558 0" />
<geometry>
<mesh filename="package:///servo.stl"/>
</geometry>
</collision>
<inertial>
<origin xyz="5.4912709887992926091e-10 1.7814792349635233393e-10 -0.022543340738670421958" rpy="0 0 0"/>
<mass value="0.093399232466800610752" />
<inertia ixx="2.4292764890865188316e-05" ixy="-4.936677377929595266e-13"  ixz="1.9163164104932232372e-13" iyy="2.1087845681977408194e-05" iyz="1.9890621813240049023e-13" izz="1.3101911709957606207e-05" />
</inertial>
</link>

<link name="tube">
<visual>
<origin xyz="-1.3877787807814456755e-17 0 -0.009859364479780200613" rpy="1.570796326794896558 1.570796326794896558 0" />
<geometry>
<mesh filename="package:///tube.stl"/>
</geometry>
<material name="tube_material">
<color rgba="0.61568627450980395466 0.81176470588235294379 0.92941176470588238168 1.0"/>
</material>
</visual>
<collision>
<origin xyz="-1.3877787807814456755e-17 0 -0.009859364479780200613" rpy="1.570796326794896558 1.570796326794896558 0" />
<geometry>
<mesh filename="package:///tube.stl"/>
</geometry>
</collision>
<inertial>
<origin xyz="-0.093644322751974831687 -7.9196223765219620537e-11 -0.0098593640573185412079" rpy="0 0 0"/>
<mass value="0.22962996415282821427" />
<inertia ixx="1.6542633726599465085e-05" ixy="-7.1610702985942383269e-13"  ixz="7.703350553304966414e-12" iyy="0.0007572461571922548115" iyz="6.8500618598074219517e-13" izz="0.00075885016345083569807" />
</inertial>
</link>

<link name="tube_2">
<visual>
<origin xyz="1.3877787807814456755e-17 0 -0.0098593644797801971436" rpy="1.570796326794896558 1.570796326794896558 0" />
<geometry>
<mesh filename="package:///tube.stl"/>
</geometry>
<material name="tube_material">
<color rgba="0.61568627450980395466 0.81176470588235294379 0.92941176470588238168 1.0"/>
</material>
</visual>
<collision>
<origin xyz="1.3877787807814456755e-17 0 -0.0098593644797801971436" rpy="1.570796326794896558 1.570796326794896558 0" />
<geometry>
<mesh filename="package:///tube.stl"/>
</geometry>
</collision>
<inertial>
<origin xyz="-0.093644322751974803931 -7.919622399204080338e-11 -0.0098593640573185429427" rpy="0 0 0"/>
<mass value="0.22962996415282821427" />
<inertia ixx="1.6542633726599465085e-05" ixy="-7.1610701043807385852e-13"  ixz="7.7033504849440625621e-12" iyy="0.00075724615719225546202" iyz="6.8500620343386295575e-13" izz="0.00075885016345083569807" />
</inertial>
</link>

<link name="link">
<visual>
<origin xyz="-0.028761368444492452223 -6.9388939039072283776e-18 -0.0029999999999999471534" rpy="1.1900733130542982356e-17 -1.2211314860100070848e-17 -7.8217795855221370653e-17" />
<geometry>
<mesh filename="package:///link.stl"/>
</geometry>
<material name="link_material">
<color rgba="0.61568627450980395466 0.81176470588235294379 0.92941176470588238168 1.0"/>
</material>
</visual>
<collision>
<origin xyz="-0.028761368444492452223 -6.9388939039072283776e-18 -0.0029999999999999471534" rpy="1.1900733130542982356e-17 -1.2211314860100070848e-17 -7.8217795855221370653e-17" />
<geometry>
<mesh filename="package:///link.stl"/>
</geometry>
</collision>
<inertial>
<origin xyz="-0.014380684222246226112 -7.9924495699086997676e-18 -0.0014999999999999471222" rpy="0 0 0"/>
<mass value="0.0039283402337506444918" />
<inertia ixx="6.0771649686119339228e-08" ixy="-3.0266158769480650219e-23"  ixz="6.1951517681224883094e-24" iyy="4.8917487284790213221e-07" iyz="3.1671271021650150186e-23" izz="5.4405401218339539119e-07" />
</inertial>
</link>

<joint name="gripper" type="revolute">
<origin xyz="-0.18503519892692563142 -0.010844984091818332672 -0.0098593644797802040824" rpy="-1.570796326794896558 2.044537757461839541e-15 6.0078544294123473608e-14" />
<parent link="tube_2" />
<child link="link" />
<axis xyz="0 0 1"/>
<limit effort="1" velocity="20" lower="3.141592653589793116" upper="6.283185307179586232"/>
<joint_properties friction="0.0"/>
</joint>

<joint name="elbow" type="revolute">
<origin xyz="-0.18500000000000002554 3.4694469519536141888e-17 3.4694469519536141888e-18" rpy="-1.3908269104259140544e-14 -1.749432667894997864e-15 -1.5707946197513502629" />
<parent link="tube" />
<child link="tube_2" />
<axis xyz="0 0 1"/>
<limit effort="1" velocity="20" lower="0" upper="3.141592653589793116"/>
<joint_properties friction="0.0"/>
</joint>

<joint name="shoulder" type="revolute">
<origin xyz="0 -0.016000000000000000333 -0.026810000000000000497" rpy="-1.570796326794896558 -0.77832067475547572766 -3.141592653589793116" />
<parent link="servo_2" />
<child link="tube" />
<axis xyz="0 0 1"/>
<limit effort="1" velocity="20" lower="0" upper="3.141592653589793116"/>
<joint_properties friction="0.0"/>
</joint>

<joint name="base" type="revolute">
<origin xyz="0.036918666788579787563 -0.026375442291109732484 0.039301875118725959624" rpy="3.1415926535897926719 5.3028613598959552621e-16 0.48583811193006148921" />
<parent link="servo" />
<child link="servo_2" />
<axis xyz="0 0 1"/>
<limit effort="1" velocity="20" lower="0" upper="6.283185307179586232"/>
<joint_properties friction="0.0"/>
</joint>


</robot>
